Workbook
Name EMEs: Fonte!$B$2:$B$30
Name Pos_emerg_fol_est: Fonte!$G$47:$G$51
Name Pos_emerg_fol_lar: Fonte!$G$52:$G$55
Name Controle_insetos: Fonte!$G$56:$G$76
Name Fertilizante_solo: Fonte!$G$2:$G$14
Name CategoriaFiltro: Fonte!$F$2:$F$117
Name Manejo_doencas: Fonte!$G$77:$G$85
Name Tratamento_sementes: Fonte!$G$15:$G$27
Name Dessec_pre_plantio: Fonte!$G$28:$G$44
Name Pre_emerg_pl_apl: Fonte!$G$45:$G$46
Name Dessec_pre_col: Fonte!$G$92:$G$112
Name Nutricao_foliar: Fonte!$G$86:$G$91
Name Estados: Fonte!$A$2:$A$30

Sheet Cadastro Propriedade
A1: Nome do Produtor (a) Líder: | B1: Rodrigo de Souza Dias Gutierrez
A2: CPF /CNPJ Produtor (a) Líder: | B2: 114.860.168-63
A3: Nome da Propriedade: | B3: Fazenda Ipê Amarelo
A4: Inscrição Estadual: | C4: Estado: | D4: TO
A5: Município:
A6: Órgão Estadual Ambiental: | B6: =IF($D$4="","",VLOOKUP('Cadastro Propriedade'!D$4,Fonte!A2:B30,2,FALSE)) -> TO-ADAPEC | C6: No Órgão Ambiental:
A7: Área Própria: | B7: 220 | C7: ha
A8: Área Arrendada: | B8: 0 | C8: ha
A9: Área Total: | B9: 220 | C9: ha
A11: CAR1 | B11: CAR2 | C11: CAR3 | D11: CAR4
A14: Sócios | B14: CPF / CNPJ Sócio | C14: Celular | D14: % | E14: e-mail
A20: Contato | B20: CPF / CNPJ Sócio | C20: Celular | D20: Cargo | E20: e-mail

Sheet Áreas de Plantio
A1: Propriedade | B1: Talhão ou Bloco | C1: Variedade | D1: Área (ha) | E1: Data Plantio
A2: =IF('Cadastro Propriedade'!B$3="","",'Cadastro Propriedade'!B$3) -> Fazenda Ipê Amarelo | B2: Talhão 1 | C2: Mika | D2: 500 | E2: 46064
A3: =IF('Cadastro Propriedade'!B$3="","",'Cadastro Propriedade'!B$3) -> Fazenda Ipê Amarelo | B3: Talhão 2
A4: =IF('Cadastro Propriedade'!B$3="","",'Cadastro Propriedade'!B$3) -> Fazenda Ipê Amarelo | B4: Talhão 3
A5: =IF('Cadastro Propriedade'!B$3="","",'Cadastro Propriedade'!B$3) -> Fazenda Ipê Amarelo
A6: =IF('Cadastro Propriedade'!B$3="","",'Cadastro Propriedade'!B$3) -> Fazenda Ipê Amarelo
A7: =IF('Cadastro Propriedade'!B$3="","",'Cadastro Propriedade'!B$3) -> Fazenda Ipê Amarelo
A8: =IF('Cadastro Propriedade'!B$3="","",'Cadastro Propriedade'!B$3) -> Fazenda Ipê Amarelo
A9: =IF('Cadastro Propriedade'!B$3="","",'Cadastro Propriedade'!B$3) -> Fazenda Ipê Amarelo
A10: =IF('Cadastro Propriedade'!B$3="","",'Cadastro Propriedade'!B$3) -> Fazenda Ipê Amarelo

Sheet Análise de Solo
A1: Propriedade | B1: Talhão ou Bloco | C1: Variedade | D1: Área (ha) | E1: Amostra de Solo | F1: Análise Físico Química | G1: ph do Solo >= 6,0 | H1: Correção ph do Solo | I1: Calcáreo kg/ha | J1: Anexo Análise de Solo
A2: =IF('Cadastro Propriedade'!B$3="","",'Cadastro Propriedade'!B$3) -> Fazenda Ipê Amarelo | B2: ='Áreas de Plantio'!B2 -> Talhão 1 | C2: =IF('Áreas de Plantio'!C2="","",'Áreas de Plantio'!C2) -> Mika | D2: =IF('Áreas de Plantio'!D2="","",'Áreas de Plantio'!D2) -> 500 | E2: Sim | F2: Sim | G2: Sim | H2: Sim | I2: 3000
A3: =IF('Cadastro Propriedade'!B$3="","",'Cadastro Propriedade'!B$3) -> Fazenda Ipê Amarelo | B3: ='Áreas de Plantio'!B3 -> Talhão 2 | C3: =IF('Áreas de Plantio'!C3="","",'Áreas de Plantio'!C3)
A4: =IF('Cadastro Propriedade'!B$3="","",'Cadastro Propriedade'!B$3) -> Fazenda Ipê Amarelo | B4: ='Áreas de Plantio'!B4 -> Talhão 3 | C4: =IF('Áreas de Plantio'!C4="","",'Áreas de Plantio'!C4)
A5: =IF('Cadastro Propriedade'!B$3="","",'Cadastro Propriedade'!B$3) -> Fazenda Ipê Amarelo
A6: =IF('Cadastro Propriedade'!B$3="","",'Cadastro Propriedade'!B$3) -> Fazenda Ipê Amarelo
A7: =IF('Cadastro Propriedade'!B$3="","",'Cadastro Propriedade'!B$3) -> Fazenda Ipê Amarelo
A8: =IF('Cadastro Propriedade'!B$3="","",'Cadastro Propriedade'!B$3) -> Fazenda Ipê Amarelo
A9: =IF('Cadastro Propriedade'!B$3="","",'Cadastro Propriedade'!B$3) -> Fazenda Ipê Amarelo
A10: =IF('Cadastro Propriedade'!B$3="","",'Cadastro Propriedade'!B$3) -> Fazenda Ipê Amarelo

Sheet Full
A1: Propriedade | B1: Talhão ou Bloco | C1: Variedade | D1: Área (ha) | E1: Uso | F1: Produto | G1: Composição | H1: Dose | I1: Unidade de Dose | J1: Volume Calda l/ha | L1: Data Uso
A2: =IF('Cadastro Propriedade'!B$3="","",'Cadastro Propriedade'!B$3) -> Fazenda Ipê Amarelo | B2: Talhão 1 | C2: Talhão 1 | D2: 500 | E2: Dessecação Pré Plantio | F2: Roundup Transorb | G2: =IF($F2="","",VLOOKUP($F2,Fonte!$G$2:$I$119,2,FALSE)) -> Glifosato 480 g/l | H2: 2 | I2: =IF($F2="","",VLOOKUP($F2,Fonte!$G$2:$I$119,3,FALSE)) -> l/ha
A3: =IF('Cadastro Propriedade'!B$3="","",'Cadastro Propriedade'!B$3) -> Fazenda Ipê Amarelo | B3: Talhão 1 | C3: Talhão 1 | D3: 500 | E3: Fertilizante Solo | F3: NPK 18-00-18 | G3: =IF($F3="","",VLOOKUP($F3,Fonte!$G$2:$I$119,2,FALSE)) -> N 18%-P 00%-K 18% | H3: 200 | I3: =IF($F3="","",VLOOKUP($F3,Fonte!$G$2:$I$119,3,FALSE)) -> kg/ha
A4: =IF('Cadastro Propriedade'!B$3="","",'Cadastro Propriedade'!B$3) -> Fazenda Ipê Amarelo

Sheet Dessecacao Pre Plantio
A1: Propriedade | B1: Talhão ou Bloco | C1: Variedade | D1: Área (ha) | E1: Uso | F1: Produto | G1: Composição | H1: Dose | I1: Unidade de Dose | J1: Volume Calda l/ha | L1: Data Uso
A2: =IF('Cadastro Propriedade'!B$3="","",'Cadastro Propriedade'!B$3) -> Fazenda Ipê Amarelo | B2: Talhão 1 | C2: Talhão 1 | D2: 500 | E2: Dessecação Pré Plantio | F2: Roundup Transorb | G2: =IF($F2="","",VLOOKUP($F2,Fonte!$G$2:$I$119,2,FALSE)) -> Glifosato 480 g/l | H2: 2 | I2: =IF($F2="","",VLOOKUP($F2,Fonte!$G$2:$I$119,3,FALSE)) -> l/ha
A3: =IF('Cadastro Propriedade'!B$3="","",'Cadastro Propriedade'!B$3) -> Fazenda Ipê Amarelo | B3: Talhão 1 | C3: Talhão 1 | D3: 500 | E3: Dessecação Pré Plantio | F3: Glufosinato Genérico 200 SL | G3: =IF($F3="","",VLOOKUP($F3,Fonte!$G$2:$I$119,2,FALSE)) -> Glufosinato 200 g/l | H3: 3 | I3: =IF($F3="","",VLOOKUP($F3,Fonte!$G$2:$I$119,3,FALSE)) -> l/ha
A4: =IF('Cadastro Propriedade'!B$3="","",'Cadastro Propriedade'!B$3) -> Fazenda Ipê Amarelo | E4: Tratamento Sementes

Sheet Tratamento Semente
A1: Propriedade | B1: Talhão ou Bloco | C1: Variedade | D1: Área (ha) | E1: Uso | F1: Produto | G1: Composição | H1: Dose | I1: Unidade de Dose | J1: Volume Calda l/ha | K1: Data Uso
A2: =IF('Cadastro Propriedade'!B$3="","",'Cadastro Propriedade'!B$3) -> Fazenda Ipê Amarelo | B2: Talhão 1 | C2: Mika | D2: 500 | E2: Tratamento Sementes | F2: Fipronil Genérico 250 FS | G2: =IF($F2="","",VLOOKUP($F2,Fonte!$G$2:$I$119,2,FALSE)) -> Fipronil 250 g/l | H2: 0.1 | I2: =IF($F2="","",VLOOKUP($F2,Fonte!$G$2:$I$119,3,FALSE)) -> ml/kg semente | J2: 10
A3: =IF('Cadastro Propriedade'!B$3="","",'Cadastro Propriedade'!B$3) -> Fazenda Ipê Amarelo | B3: Talhão 1 | C3: Mika | D3: 500 | E3: Tratamento Sementes | F3: Certeza N | G3: =IF($F3="","",VLOOKUP($F3,Fonte!$G$2:$I$119,2,FALSE)) -> Tiofanato Metílico 350 g/l + Fluazinam 52,5 g/l | H3: 0.05 | I3: =IF($F3="","",VLOOKUP($F3,Fonte!$G$2:$I$119,3,FALSE)) -> ml/kg semente | J3: 10
A4: =IF('Cadastro Propriedade'!B$3="","",'Cadastro Propriedade'!B$3) -> Fazenda Ipê Amarelo | B4: Talhão 1 | C4: Mika | D4: 500 | E4: Tratamento Sementes | F4: Simplex | G4: =IF($F4="","",VLOOKUP($F4,Fonte!$G$2:$I$119,2,FALSE)) -> Simplex | H4: 0.2 | I4: =IF($F4="","",VLOOKUP($F4,Fonte!$G$2:$I$119,3,FALSE)) -> ml/kg semente | J4: 10
A5: =IF('Cadastro Propriedade'!B$3="","",'Cadastro Propriedade'!B$3) -> Fazenda Ipê Amarelo | B5: Talhão 1 | C5: Mika | D5: 500 | E5: Tratamento Sementes | F5: Stimulate | G5: =IF($F5="","",VLOOKUP($F5,Fonte!$G$2:$I$119,2,FALSE)) -> Stimulate | H5: 0.3 | I5: =IF($F5="","",VLOOKUP($F5,Fonte!$G$2:$I$119,3,FALSE)) -> ml/kg semente | J5: 10
A6: =IF('Cadastro Propriedade'!B$3="","",'Cadastro Propriedade'!B$3) -> Fazenda Ipê Amarelo | D6: 500 | G6: =IF($F6="","",VLOOKUP($F6,Fonte!$G$2:$I$119,2,FALSE)) | I6: =IF($F6="","",VLOOKUP($F6,Fonte!$G$2:$I$119,3,FALSE))
A7: =IF('Cadastro Propriedade'!B$3="","",'Cadastro Propriedade'!B$3) -> Fazenda Ipê Amarelo | D7: 500 | G7: =IF($F7="","",VLOOKUP($F7,Fonte!$G$2:$I$119,2,FALSE)) | I7: =IF($F7="","",VLOOKUP($F7,Fonte!$G$2:$I$119,3,FALSE))

Sheet Adubação
A1: Propriedade | B1: Talhão ou Bloco | C1: Variedade | D1: Área (ha) | E1: Uso | F1: Produto | G1: Composição | H1: Dose | I1: Unidade de Dose | J1: Volume Calda l/ha | K1: Data Uso
A2: =IF('Cadastro Propriedade'!B$3="","",'Cadastro Propriedade'!B$3) -> Fazenda Ipê Amarelo | B2: Talhão 1 | C2: Mika | D2: 500 | E2: Fertilizante Solo | F2: NPK 20-00-20 | G2: =IF($F2="","",VLOOKUP($F2,Fonte!$G$2:$I$119,2,FALSE)) -> N 20%-P 00%-K 20% | H2: 0.1 | I2: =IF($F2="","",VLOOKUP($F2,Fonte!$G$2:$I$119,3,FALSE)) -> kg/ha | J2: 10
A3: =IF('Cadastro Propriedade'!B$3="","",'Cadastro Propriedade'!B$3) -> Fazenda Ipê Amarelo | B3: Talhão 1 | C3: Mika | D3: 500 | E3: Fertilizante Solo | F3: Enxofre | G3: =IF($F3="","",VLOOKUP($F3,Fonte!$G$2:$I$119,2,FALSE)) | H3: 0.05 | I3: =IF($F3="","",VLOOKUP($F3,Fonte!$G$2:$I$119,3,FALSE)) -> kg/ha | J3: 10
A4: =IF('Cadastro Propriedade'!B$3="","",'Cadastro Propriedade'!B$3) -> Fazenda Ipê Amarelo | B4: Talhão 1 | C4: Mika | D4: 500 | E4: Fertilizante Solo | F4: Manganês | G4: =IF($F4="","",VLOOKUP($F4,Fonte!$G$2:$I$119,2,FALSE)) | H4: 0.2 | I4: =IF($F4="","",VLOOKUP($F4,Fonte!$G$2:$I$119,3,FALSE)) -> kg/ha | J4: 10
A5: =IF('Cadastro Propriedade'!B$3="","",'Cadastro Propriedade'!B$3) -> Fazenda Ipê Amarelo | B5: Talhão 1 | C5: Mika | D5: 500 | E5: Fertilizante Solo | F5: Níquel | G5: =IF($F5="","",VLOOKUP($F5,Fonte!$G$2:$I$119,2,FALSE)) | H5: 0.3 | I5: =IF($F5="","",VLOOKUP($F5,Fonte!$G$2:$I$119,3,FALSE)) -> kg/ha | J5: 10
A6: =IF('Cadastro Propriedade'!B$3="","",'Cadastro Propriedade'!B$3) -> Fazenda Ipê Amarelo | D6: 500 | G6: =IF($F6="","",VLOOKUP($F6,Fonte!$G$2:$I$119,2,FALSE)) | I6: =IF($F6="","",VLOOKUP($F6,Fonte!$G$2:$I$119,3,FALSE))
A7: =IF('Cadastro Propriedade'!B$3="","",'Cadastro Propriedade'!B$3) -> Fazenda Ipê Amarelo | D7: 500 | G7: =IF($F7="","",VLOOKUP($F7,Fonte!$G$2:$I$119,2,FALSE)) | I7: =IF($F7="","",VLOOKUP($F7,Fonte!$G$2:$I$119,3,FALSE))

Sheet Operação Plantio
A1: Propriedade | B1: Talhão ou Bloco | C1: Variedade | D1: Área (ha) | E1: Data Plantio | F1: Plantadeira a Vácuo | G1: Modelo Plantadeira Aprovado | H1: Disco Plantio
A2: =IF('Cadastro Propriedade'!B$3="","",'Cadastro Propriedade'!B$3) -> Fazenda Ipê Amarelo | B2: Talhão 1 | C2: Mika | D2: 500 | E2: 46064 | F2: Sim | G2: Sim | H2: 0,8 mm
A3: =IF('Cadastro Propriedade'!B$3="","",'Cadastro Propriedade'!B$3) -> Fazenda Ipê Amarelo | B3: Talhão 2
A4: =IF('Cadastro Propriedade'!B$3="","",'Cadastro Propriedade'!B$3) -> Fazenda Ipê Amarelo | B4: Talhão 3
A5: =IF('Cadastro Propriedade'!B$3="","",'Cadastro Propriedade'!B$3) -> Fazenda Ipê Amarelo
A6: =IF('Cadastro Propriedade'!B$3="","",'Cadastro Propriedade'!B$3) -> Fazenda Ipê Amarelo
A7: =IF('Cadastro Propriedade'!B$3="","",'Cadastro Propriedade'!B$3) -> Fazenda Ipê Amarelo
A8: =IF('Cadastro Propriedade'!B$3="","",'Cadastro Propriedade'!B$3) -> Fazenda Ipê Amarelo
A9: =IF('Cadastro Propriedade'!B$3="","",'Cadastro Propriedade'!B$3) -> Fazenda Ipê Amarelo
A10: =IF('Cadastro Propriedade'!B$3="","",'Cadastro Propriedade'!B$3) -> Fazenda Ipê Amarelo

Sheet Plante e Aplique
A1: Propriedade | B1: Talhão ou Bloco | C1: Variedade | D1: Área (ha) | E1: Uso | F1: Produto | G1: Composição | H1: Dose | I1: Unidade de Dose | J1: Volume Calda l/ha | K1: Data Uso
A2: =IF('Cadastro Propriedade'!B$3="","",'Cadastro Propriedade'!B$3) -> Fazenda Ipê Amarelo | B2: Talhão 1 | C2: Mika | D2: 500 | E2: Pré Emergente Plante Aplique | F2: Plateau | G2: =IF($F2="","",VLOOKUP($F2,Fonte!$G$2:$I$119,2,FALSE)) -> Imazapic 700 g/kg | H2: 70 | I2: =IF($F2="","",VLOOKUP($F2,Fonte!$G$2:$I$119,3,FALSE)) -> g/ha | J2: 10
A3: =IF('Cadastro Propriedade'!B$3="","",'Cadastro Propriedade'!B$3) -> Fazenda Ipê Amarelo | G3: =IF($F3="","",VLOOKUP($F3,Fonte!$G$2:$I$119,2,FALSE)) | H3: 0.05 | I3: =IF($F3="","",VLOOKUP($F3,Fonte!$G$2:$I$119,3,FALSE)) | J3: 10
A4: =IF('Cadastro Propriedade'!B$3="","",'Cadastro Propriedade'!B$3) -> Fazenda Ipê Amarelo | G4: =IF($F4="","",VLOOKUP($F4,Fonte!$G$2:$I$119,2,FALSE)) | H4: 0.2 | I4: =IF($F4="","",VLOOKUP($F4,Fonte!$G$2:$I$119,3,FALSE)) | J4: 10
A5: =IF('Cadastro Propriedade'!B$3="","",'Cadastro Propriedade'!B$3) -> Fazenda Ipê Amarelo | G5: =IF($F5="","",VLOOKUP($F5,Fonte!$G$2:$I$119,2,FALSE)) | H5: 0.3 | I5: =IF($F5="","",VLOOKUP($F5,Fonte!$G$2:$I$119,3,FALSE)) | J5: 10
A6: =IF('Cadastro Propriedade'!B$3="","",'Cadastro Propriedade'!B$3) -> Fazenda Ipê Amarelo | G6: =IF($F6="","",VLOOKUP($F6,Fonte!$G$2:$I$119,2,FALSE)) | I6: =IF($F6="","",VLOOKUP($F6,Fonte!$G$2:$I$119,3,FALSE))
A7: =IF('Cadastro Propriedade'!B$3="","",'Cadastro Propriedade'!B$3) -> Fazenda Ipê Amarelo | G7: =IF($F7="","",VLOOKUP($F7,Fonte!$G$2:$I$119,2,FALSE)) | I7: =IF($F7="","",VLOOKUP($F7,Fonte!$G$2:$I$119,3,FALSE))

Sheet Pós Emergente Folhas Estreitas
A1: Propriedade | B1: Talhão ou Bloco | C1: Variedade | D1: Área (ha) | E1: Uso | F1: Produto | G1: Composição | H1: Dose | I1: Unidade de Dose | J1: Volume Calda l/ha | K1: Data Uso
A2: =IF('Cadastro Propriedade'!B$3="","",'Cadastro Propriedade'!B$3) -> Fazenda Ipê Amarelo | B2: Talhão 1 | C2: Mika | D2: 500 | E2: Pós Emergente Folhas Estreitas | F2: Select | G2: =IF($F2="","",VLOOKUP($F2,Fonte!$G$2:$I$119,2,FALSE)) -> Cletodim 240 g/l | H2: 0.8 | I2: =IF($F2="","",VLOOKUP($F2,Fonte!$G$2:$I$119,3,FALSE)) -> l/ha | J2: 120
A3: =IF('Cadastro Propriedade'!B$3="","",'Cadastro Propriedade'!B$3) -> Fazenda Ipê Amarelo | G3: =IF($F3="","",VLOOKUP($F3,Fonte!$G$2:$I$119,2,FALSE)) | H3: 0.05 | I3: =IF($F3="","",VLOOKUP($F3,Fonte!$G$2:$I$119,3,FALSE))
A4: =IF('Cadastro Propriedade'!B$3="","",'Cadastro Propriedade'!B$3) -> Fazenda Ipê Amarelo | G4: =IF($F4="","",VLOOKUP($F4,Fonte!$G$2:$I$119,2,FALSE)) | H4: 0.2 | I4: =IF($F4="","",VLOOKUP($F4,Fonte!$G$2:$I$119,3,FALSE))
A5: =IF('Cadastro Propriedade'!B$3="","",'Cadastro Propriedade'!B$3) -> Fazenda Ipê Amarelo | G5: =IF($F5="","",VLOOKUP($F5,Fonte!$G$2:$I$119,2,FALSE)) | H5: 0.3 | I5: =IF($F5="","",VLOOKUP($F5,Fonte!$G$2:$I$119,3,FALSE))
A6: =IF('Cadastro Propriedade'!B$3="","",'Cadastro Propriedade'!B$3) -> Fazenda Ipê Amarelo | G6: =IF($F6="","",VLOOKUP($F6,Fonte!$G$2:$I$119,2,FALSE)) | I6: =IF($F6="","",VLOOKUP($F6,Fonte!$G$2:$I$119,3,FALSE))
A7: =IF('Cadastro Propriedade'!B$3="","",'Cadastro Propriedade'!B$3) -> Fazenda Ipê Amarelo | G7: =IF($F7="","",VLOOKUP($F7,Fonte!$G$2:$I$119,2,FALSE)) | I7: =IF($F7="","",VLOOKUP($F7,Fonte!$G$2:$I$119,3,FALSE))

Sheet Pós Emergente Folhas Largas
A1: Propriedade | B1: Talhão ou Bloco | C1: Variedade | D1: Área (ha) | E1: Uso | F1: Produto | G1: Composição | H1: Dose | I1: Unidade de Dose | J1: Volume Calda l/ha | K1: Data Uso
A2: =IF('Cadastro Propriedade'!B$3="","",'Cadastro Propriedade'!B$3) -> Fazenda Ipê Amarelo | B2: Talhão 1 | C2: Mika | D2: 500 | E2: Pós Emergente Folhas Largas | F2: Imazetapir Nortox | G2: =IF($F2="","",VLOOKUP($F2,Fonte!$G$2:$I$119,2,FALSE)) -> Imazetapir 212 g/l | H2: 0.8 | I2: =IF($F2="","",VLOOKUP($F2,Fonte!$G$2:$I$119,3,FALSE)) -> l/ha | J2: 120
A3: =IF('Cadastro Propriedade'!B$3="","",'Cadastro Propriedade'!B$3) -> Fazenda Ipê Amarelo | G3: =IF($F3="","",VLOOKUP($F3,Fonte!$G$2:$I$119,2,FALSE)) | H3: 0.05 | I3: =IF($F3="","",VLOOKUP($F3,Fonte!$G$2:$I$119,3,FALSE))
A4: =IF('Cadastro Propriedade'!B$3="","",'Cadastro Propriedade'!B$3) -> Fazenda Ipê Amarelo | G4: =IF($F4="","",VLOOKUP($F4,Fonte!$G$2:$I$119,2,FALSE)) | H4: 0.2 | I4: =IF($F4="","",VLOOKUP($F4,Fonte!$G$2:$I$119,3,FALSE))
A5: =IF('Cadastro Propriedade'!B$3="","",'Cadastro Propriedade'!B$3) -> Fazenda Ipê Amarelo | G5: =IF($F5="","",VLOOKUP($F5,Fonte!$G$2:$I$119,2,FALSE)) | H5: 0.3 | I5: =IF($F5="","",VLOOKUP($F5,Fonte!$G$2:$I$119,3,FALSE))
A6: =IF('Cadastro Propriedade'!B$3="","",'Cadastro Propriedade'!B$3) -> Fazenda Ipê Amarelo | G6: =IF($F6="","",VLOOKUP($F6,Fonte!$G$2:$I$119,2,FALSE)) | I6: =IF($F6="","",VLOOKUP($F6,Fonte!$G$2:$I$119,3,FALSE))
A7: =IF('Cadastro Propriedade'!B$3="","",'Cadastro Propriedade'!B$3) -> Fazenda Ipê Amarelo | G7: =IF($F7="","",VLOOKUP($F7,Fonte!$G$2:$I$119,2,FALSE)) | I7: =IF($F7="","",VLOOKUP($F7,Fonte!$G$2:$I$119,3,FALSE))

Sheet Controle Insetos
A1: Propriedade | B1: Talhão ou Bloco | C1: Variedade | D1: Área (ha) | E1: Uso | F1: Produto | G1: Composição | H1: Dose | I1: Unidade de Dose | J1: Volume Calda l/ha | K1: Data Uso
A2: =IF('Cadastro Propriedade'!B$3="","",'Cadastro Propriedade'!B$3) -> Fazenda Ipê Amarelo | B2: Talhão 1 | C2: Mika | D2: 500 | E2: Controle de Insetos | F2: Acefato CCAB 750 SP | G2: =IF($F2="","",VLOOKUP($F2,Fonte!$G$2:$I$119,2,FALSE)) -> Acefato 750 g/kg | H2: 1 | I2: =IF($F2="","",VLOOKUP($F2,Fonte!$G$2:$I$119,3,FALSE)) -> kg/ha | J2: 120
A3: =IF('Cadastro Propriedade'!B$3="","",'Cadastro Propriedade'!B$3) -> Fazenda Ipê Amarelo | G3: =IF($F3="","",VLOOKUP($F3,Fonte!$G$2:$I$119,2,FALSE)) | I3: =IF($F3="","",VLOOKUP($F3,Fonte!$G$2:$I$119,3,FALSE))
A4: =IF('Cadastro Propriedade'!B$3="","",'Cadastro Propriedade'!B$3) -> Fazenda Ipê Amarelo | G4: =IF($F4="","",VLOOKUP($F4,Fonte!$G$2:$I$119,2,FALSE)) | I4: =IF($F4="","",VLOOKUP($F4,Fonte!$G$2:$I$119,3,FALSE))
A5: =IF('Cadastro Propriedade'!B$3="","",'Cadastro Propriedade'!B$3) -> Fazenda Ipê Amarelo | G5: =IF($F5="","",VLOOKUP($F5,Fonte!$G$2:$I$119,2,FALSE)) | I5: =IF($F5="","",VLOOKUP($F5,Fonte!$G$2:$I$119,3,FALSE))
A6: =IF('Cadastro Propriedade'!B$3="","",'Cadastro Propriedade'!B$3) -> Fazenda Ipê Amarelo | G6: =IF($F6="","",VLOOKUP($F6,Fonte!$G$2:$I$119,2,FALSE)) | I6: =IF($F6="","",VLOOKUP($F6,Fonte!$G$2:$I$119,3,FALSE))
A7: =IF('Cadastro Propriedade'!B$3="","",'Cadastro Propriedade'!B$3) -> Fazenda Ipê Amarelo | G7: =IF($F7="","",VLOOKUP($F7,Fonte!$G$2:$I$119,2,FALSE)) | I7: =IF($F7="","",VLOOKUP($F7,Fonte!$G$2:$I$119,3,FALSE))

Sheet Manejo Doenças 1
A1: Propriedade | B1: Talhão ou Bloco | C1: Variedade | D1: Área (ha) | E1: Uso | F1: Produto | G1: Composição | H1: Dose | I1: Unidade de Dose | J1: Volume Calda l/ha | K1: Data Uso
A2: =IF('Cadastro Propriedade'!B$3="","",'Cadastro Propriedade'!B$3) -> Fazenda Ipê Amarelo | B2: Talhão 1 | C2: Mika | D2: 500 | E2: Manejo de Doenças | F2: Orkestra | G2: =IF($F2="","",VLOOKUP($F2,Fonte!$G$2:$I$119,2,FALSE)) -> Fluxapiroxade 133 g/l + Piraclostrobina 333 g/l | H2: 0.3 | I2: =IF($F2="","",VLOOKUP($F2,Fonte!$G$2:$I$119,3,FALSE)) -> l/ha | J2: 120
A3: =IF('Cadastro Propriedade'!B$3="","",'Cadastro Propriedade'!B$3) -> Fazenda Ipê Amarelo | B3: Talhão 1 | C3: Mika | D3: 500 | E3: Manejo de Doenças | F3: Score Flexi | G3: =IF($F3="","",VLOOKUP($F3,Fonte!$G$2:$I$119,2,FALSE)) -> Difenoconazol 250 g/l + Propiconazol 250 g/l | H3: 0.5 | I3: =IF($F3="","",VLOOKUP($F3,Fonte!$G$2:$I$119,3,FALSE)) -> l/ha | J3: 120
A4: =IF('Cadastro Propriedade'!B$3="","",'Cadastro Propriedade'!B$3) -> Fazenda Ipê Amarelo | G4: =IF($F4="","",VLOOKUP($F4,Fonte!$G$2:$I$119,2,FALSE)) | I4: =IF($F4="","",VLOOKUP($F4,Fonte!$G$2:$I$119,3,FALSE))
A5: =IF('Cadastro Propriedade'!B$3="","",'Cadastro Propriedade'!B$3) -> Fazenda Ipê Amarelo | G5: =IF($F5="","",VLOOKUP($F5,Fonte!$G$2:$I$119,2,FALSE)) | I5: =IF($F5="","",VLOOKUP($F5,Fonte!$G$2:$I$119,3,FALSE))
A6: =IF('Cadastro Propriedade'!B$3="","",'Cadastro Propriedade'!B$3) -> Fazenda Ipê Amarelo | G6: =IF($F6="","",VLOOKUP($F6,Fonte!$G$2:$I$119,2,FALSE)) | I6: =IF($F6="","",VLOOKUP($F6,Fonte!$G$2:$I$119,3,FALSE))
A7: =IF('Cadastro Propriedade'!B$3="","",'Cadastro Propriedade'!B$3) -> Fazenda Ipê Amarelo | G7: =IF($F7="","",VLOOKUP($F7,Fonte!$G$2:$I$119,2,FALSE)) | I7: =IF($F7="","",VLOOKUP($F7,Fonte!$G$2:$I$119,3,FALSE))

Sheet Manejo Doenças 2
A1: Propriedade | B1: Talhão ou Bloco | C1: Variedade | D1: Área (ha) | E1: Uso | F1: Produto | G1: Composição | H1: Dose | I1: Unidade de Dose | J1: Volume Calda l/ha | K1: Data Uso
A2: =IF('Cadastro Propriedade'!B$3="","",'Cadastro Propriedade'!B$3) -> Fazenda Ipê Amarelo | B2: Talhão 1 | C2: Mika | D2: 500 | E2: Manejo de Doenças | F2: Orkestra | G2: =IF($F2="","",VLOOKUP($F2,Fonte!$G$2:$I$119,2,FALSE)) -> Fluxapiroxade 133 g/l + Piraclostrobina 333 g/l | H2: 0.3 | I2: =IF($F2="","",VLOOKUP($F2,Fonte!$G$2:$I$119,3,FALSE)) -> l/ha | J2: 120
A3: =IF('Cadastro Propriedade'!B$3="","",'Cadastro Propriedade'!B$3) -> Fazenda Ipê Amarelo | B3: Talhão 1 | C3: Mika | D3: 500 | E3: Manejo de Doenças | F3: Score Flexi | G3: =IF($F3="","",VLOOKUP($F3,Fonte!$G$2:$I$119,2,FALSE)) -> Difenoconazol 250 g/l + Propiconazol 250 g/l | H3: 0.5 | I3: =IF($F3="","",VLOOKUP($F3,Fonte!$G$2:$I$119,3,FALSE)) -> l/ha | J3: 120
A4: =IF('Cadastro Propriedade'!B$3="","",'Cadastro Propriedade'!B$3) -> Fazenda Ipê Amarelo | G4: =IF($F4="","",VLOOKUP($F4,Fonte!$G$2:$I$119,2,FALSE)) | I4: =IF($F4="","",VLOOKUP($F4,Fonte!$G$2:$I$119,3,FALSE))
A5: =IF('Cadastro Propriedade'!B$3="","",'Cadastro Propriedade'!B$3) -> Fazenda Ipê Amarelo | G5: =IF($F5="","",VLOOKUP($F5,Fonte!$G$2:$I$119,2,FALSE)) | I5: =IF($F5="","",VLOOKUP($F5,Fonte!$G$2:$I$119,3,FALSE))
A6: =IF('Cadastro Propriedade'!B$3="","",'Cadastro Propriedade'!B$3) -> Fazenda Ipê Amarelo | G6: =IF($F6="","",VLOOKUP($F6,Fonte!$G$2:$I$119,2,FALSE)) | I6: =IF($F6="","",VLOOKUP($F6,Fonte!$G$2:$I$119,3,FALSE))
A7: =IF('Cadastro Propriedade'!B$3="","",'Cadastro Propriedade'!B$3) -> Fazenda Ipê Amarelo | G7: =IF($F7="","",VLOOKUP($F7,Fonte!$G$2:$I$119,2,FALSE)) | I7: =IF($F7="","",VLOOKUP($F7,Fonte!$G$2:$I$119,3,FALSE))

Sheet Nutrição Foliar
A1: Propriedade | B1: Talhão ou Bloco | C1: Variedade | D1: Área (ha) | E1: Uso | F1: Produto | G1: Composição | H1: Dose | I1: Unidade de Dose | J1: Volume Calda l/ha | K1: Data Uso
A2: =IF('Cadastro Propriedade'!B$3="","",'Cadastro Propriedade'!B$3) -> Fazenda Ipê Amarelo | B2: Talhão 1 | C2: Mika | D2: 500 | E2: Nutrição Foliar | F2: Dominio | G2: =IF($F2="","",VLOOKUP($F2,Fonte!$G$2:$I$119,2,FALSE)) -> Bioestimulante | H2: 0.3 | I2: =IF($F2="","",VLOOKUP($F2,Fonte!$G$2:$I$119,3,FALSE)) -> l/ha | J2: 120
A3: =IF('Cadastro Propriedade'!B$3="","",'Cadastro Propriedade'!B$3) -> Fazenda Ipê Amarelo | B3: Talhão 1 | C3: Mika | D3: 500 | E3: Nutrição Foliar | F3: Borum | G3: =IF($F3="","",VLOOKUP($F3,Fonte!$G$2:$I$119,2,FALSE)) -> Boro 100 g/l | H3: 0.5 | I3: =IF($F3="","",VLOOKUP($F3,Fonte!$G$2:$I$119,3,FALSE)) -> l/ha | J3: 120
A4: =IF('Cadastro Propriedade'!B$3="","",'Cadastro Propriedade'!B$3) -> Fazenda Ipê Amarelo | G4: =IF($F4="","",VLOOKUP($F4,Fonte!$G$2:$I$119,2,FALSE)) | I4: =IF($F4="","",VLOOKUP($F4,Fonte!$G$2:$I$119,3,FALSE))
A5: =IF('Cadastro Propriedade'!B$3="","",'Cadastro Propriedade'!B$3) -> Fazenda Ipê Amarelo | G5: =IF($F5="","",VLOOKUP($F5,Fonte!$G$2:$I$119,2,FALSE)) | I5: =IF($F5="","",VLOOKUP($F5,Fonte!$G$2:$I$119,3,FALSE))
A6: =IF('Cadastro Propriedade'!B$3="","",'Cadastro Propriedade'!B$3) -> Fazenda Ipê Amarelo | G6: =IF($F6="","",VLOOKUP($F6,Fonte!$G$2:$I$119,2,FALSE)) | I6: =IF($F6="","",VLOOKUP($F6,Fonte!$G$2:$I$119,3,FALSE))
A7: =IF('Cadastro Propriedade'!B$3="","",'Cadastro Propriedade'!B$3) -> Fazenda Ipê Amarelo | G7: =IF($F7="","",VLOOKUP($F7,Fonte!$G$2:$I$119,2,FALSE)) | I7: =IF($F7="","",VLOOKUP($F7,Fonte!$G$2:$I$119,3,FALSE))

Sheet Dessecacao Pré Colheita
A1: Propriedade | B1: Talhão ou Bloco | C1: Variedade | D1: Área (ha) | E1: Uso | F1: Produto | G1: Composição | H1: Dose | I1: Unidade de Dose | J1: Volume Calda l/ha | K1: Data Uso
A2: =IF('Cadastro Propriedade'!B$3="","",'Cadastro Propriedade'!B$3) -> Fazenda Ipê Amarelo | B2: Talhão 1 | C2: Mika | D2: 500 | E2: Dessecação Pré Colheita | F2: Diquat Nortox | G2: =IF($F2="","",VLOOKUP($F2,Fonte!$G$2:$I$119,2,FALSE)) -> Diquat 200 g/l | H2: 1 | I2: =IF($F2="","",VLOOKUP($F2,Fonte!$G$2:$I$119,3,FALSE)) -> l/ha | J2: 120
A3: =IF('Cadastro Propriedade'!B$3="","",'Cadastro Propriedade'!B$3) -> Fazenda Ipê Amarelo
A4: =IF('Cadastro Propriedade'!B$3="","",'Cadastro Propriedade'!B$3) -> Fazenda Ipê Amarelo | G4: =IF($F4="","",VLOOKUP($F4,Fonte!$G$2:$I$119,2,FALSE)) | I4: =IF($F4="","",VLOOKUP($F4,Fonte!$G$2:$I$119,3,FALSE))
A5: =IF('Cadastro Propriedade'!B$3="","",'Cadastro Propriedade'!B$3) -> Fazenda Ipê Amarelo | G5: =IF($F5="","",VLOOKUP($F5,Fonte!$G$2:$I$119,2,FALSE)) | I5: =IF($F5="","",VLOOKUP($F5,Fonte!$G$2:$I$119,3,FALSE))
A6: =IF('Cadastro Propriedade'!B$3="","",'Cadastro Propriedade'!B$3) -> Fazenda Ipê Amarelo | G6: =IF($F6="","",VLOOKUP($F6,Fonte!$G$2:$I$119,2,FALSE)) | I6: =IF($F6="","",VLOOKUP($F6,Fonte!$G$2:$I$119,3,FALSE))
A7: =IF('Cadastro Propriedade'!B$3="","",'Cadastro Propriedade'!B$3) -> Fazenda Ipê Amarelo | G7: =IF($F7="","",VLOOKUP($F7,Fonte!$G$2:$I$119,2,FALSE)) | I7: =IF($F7="","",VLOOKUP($F7,Fonte!$G$2:$I$119,3,FALSE))

Sheet Colheita
A1: Propriedade | B1: Talhão ou Bloco | C1: Variedade | D1: Área (ha) | E1: Data Plantio | F1: Data Colheita | G1: Colheita Total kg
A2: =IF('Cadastro Propriedade'!B$3="","",'Cadastro Propriedade'!B$3) -> Fazenda Ipê Amarelo | B2: Talhão 1 | C2: Mika | D2: 500 | E2: 46064
A3: =IF('Cadastro Propriedade'!B$3="","",'Cadastro Propriedade'!B$3) -> Fazenda Ipê Amarelo | B3: Talhão 2
A4: =IF('Cadastro Propriedade'!B$3="","",'Cadastro Propriedade'!B$3) -> Fazenda Ipê Amarelo | B4: Talhão 3
A5: =IF('Cadastro Propriedade'!B$3="","",'Cadastro Propriedade'!B$3) -> Fazenda Ipê Amarelo
A6: =IF('Cadastro Propriedade'!B$3="","",'Cadastro Propriedade'!B$3) -> Fazenda Ipê Amarelo

Sheet Fonte
A1: UF | B1: EME | C1: Doses | E1: Ordem | F1: Uso | G1: Produto | H1: Composição | I1: Unidade
A2: AC | B2: AC-IDAF | C2: g/ha | E2: 1 | F2: Fertilizante Solo | G2: Boro Ulexita | H2: B2O3 43% | I2: kg/ha
A3: AL | B3: AL-ADEAL | C3: l/ha | E3: 1 | F3: Fertilizante Solo | G3: KCl | H3: K2O 60% | I3: kg/ha
A4: AP | B4: AP-DIAGRO | C4: kg/ha | E4: 1 | F4: Fertilizante Solo | G4: MAP | H4: N 11%-P 52%-K 00% | I4: kg/ha
A5: AM | B5: AM-ADAF | C5: ml/kg semente | E5: 1 | F5: Fertilizante Solo | G5: NPK 18-00-18 | H5: N 18%-P 00%-K 18% | I5: kg/ha
A6: BA | B6: BA-ADAB | C6: g/kg semente | E6: 1 | F6: Fertilizante Solo | G6: NPK 20-00-20 | H6: N 20%-P 00%-K 20% | I6: kg/ha
A7: CE | B7: CE-ADAGRI | E7: 1 | F7: Fertilizante Solo | G7: Uréia | H7: N 45% | I7: kg/ha
A8: DF | B8: DF-SEAGRI | E8: 1 | F8: Fertilizante Solo | G8: Superfosfato Simples | H8: P2O5 20%-S 10% | I8: kg/ha
A9: ES | B9: ES-IDAF | C9: Discos_de_plantio | E9: 1 | F9: Fertilizante Solo | G9: Superfosfato Triplo | H9: P2O5 45%-Ca 10% | I9: kg/ha
A10: GO | B10: GO-AGRODEFESA | C10: 0,8 mm | E10: 1 | F10: Fertilizante Solo | G10: Enxofre | I10: kg/ha
A11: MA | B11: MA-AGED | C11: 1,0 mm | E11: 1 | F11: Fertilizante Solo | G11: Manganês | I11: kg/ha
A12: MT | B12: MT-INDEA | C12: 1,2 mm | E12: 1 | F12: Fertilizante Solo | G12: Níquel | I12: kg/ha
A13: MS | B13: MS-IAGRO | E13: 1 | F13: Fertilizante Solo | G13: Zinco | I13: kg/ha
A14: MG | B14: MG-IMA | E14: 1 | F14: Fertilizante Solo | G14: Outro | H14: Outro
A15: PA | B15: PA-ADEPARÁ | E15: 2 | F15: Tratamento Sementes | G15: Fipronil Genérico 250 FS | H15: Fipronil 250 g/l | I15: ml/kg semente
A16: PB | B16: PB-SUDAP | C16: Variedades | E16: 2 | F16: Tratamento Sementes | G16: Shelter | H16: Fipronil 250 g/l | I16: ml/kg semente
A17: PR | B17: PR-ADAPAR | C17: Mika | E17: 2 | F17: Tratamento Sementes | G17: Standak | H17: Fipronil 250 g/l | I17: ml/kg semente
A18: PE | B18: PE-ADAGRO | C18: Oren | E18: 2 | F18: Tratamento Sementes | G18: Standak Top | H18: Fipronil 250 g/l + Tiofanato Metílico 225 g/l + Piraclostrobina 25 g/l | I18: ml/kg semente
A19: PI | B19: PI-ADAPI | C19: Ron | E19: 2 | F19: Tratamento Sementes | G19: Gaucho FS 600 | H19: Imidacloprid 600 g/l | I19: ml/kg semente
A20: RJ | B20: RJ-DEFESA | C20: K3 | E20: 2 | F20: Tratamento Sementes | G20: Imidacloprid FS 600 Genérico | H20: Imidacloprid 600 g/l | I20: ml/kg semente
A21: RN | B21: RN-IDIARN | C21: Victoria | E21: 2 | F21: Tratamento Sementes | G21: Simplex | H21: Simplex | I21: ml/kg semente
A22: RS | B22: RS-SEAPDR | C22: Jordan | E22: 2 | F22: Tratamento Sementes | G22: Stimulate | H22: Stimulate | I22: ml/kg semente
A23: RO | B23: RO-IDARON | C23: Anahy | E23: 2 | F23: Tratamento Sementes | G23: Aprove | H23: Tiofanato Metílico 350 g/l + Fluazinam 52,5 g/l | I23: ml/kg semente
A24: RR | B24: RR-ADERR | C24: Seda | E24: 2 | F24: Tratamento Sementes | G24: Certeza N | H24: Tiofanato Metílico 350 g/l + Fluazinam 52,5 g/l | I24: ml/kg semente
A25: SC | B25: SC-CIDASC | E25: 2 | F25: Tratamento Sementes | G25: Firmeza N | H25: Tiofanato Metílico 350 g/l + Fluazinam 52,5 g/l | I25: ml/kg semente
A26: SP | B26: SP-CDA | E26: 2 | F26: Tratamento Sementes | G26: Plust | H26: Tiofanato Metílico 350 g/l + Fluazinam 52,5 g/l | I26: ml/kg semente
A27: SE | B27: SE-EMDAGRO | C27: Sim | E27: 2 | F27: Tratamento Sementes | G27: Outro | H27: Outro
A28: TO | B28: TO-ADAPEC | C28: Não | E28: 3 | F28: Dessecação Pré Plantio | G28: Glifosato 480 SL Genérico Líquido | H28: Glifosato 360 g/l | I28: l/ha
E29: 3 | F29: Dessecação Pré Plantio | G29: Glifosato Nortox 480 SL | H29: Glifosato 360 g/l | I29: l/ha
E30: 3 | F30: Dessecação Pré Plantio | G30: Roundup Original | H30: Glifosato 360 g/l | I30: l/ha
C31: Usos | E31: 3 | F31: Dessecação Pré Plantio | G31: Roundup Original Mais | H31: Glifosato 480 g/l | I31: l/ha
C32: Fertilizante Solo | E32: 3 | F32: Dessecação Pré Plantio | G32: Roundup Transorb | H32: Glifosato 480 g/l | I32: l/ha
C33: Tratamento Sementes | E33: 3 | F33: Dessecação Pré Plantio | G33: Glifosato Genérico 500 Líquido | H33: Glifosato 500 g/l | I33: l/ha
C34: Dessecação Pré Plantio | E34: 3 | F34: Dessecação Pré Plantio | G34: Zapp QI Líquido | H34: Glifosato 500 g/l | I34: l/ha
C35: Pré Emergente Plante Aplique | E35: 3 | F35: Dessecação Pré Plantio | G35: Crucial 698 Sumitomo | H35: Glifosato 540 g/l | I35: l/ha
C36: Pós Emergente Folhas Estreitas | E36: 3 | F36: Dessecação Pré Plantio | G36: Glifosato Genérico WG 720 | H36: Glifosato 720 g/kg | I36: kg/ha
C37: Pós Emergente Folhas Largas | E37: 3 | F37: Dessecação Pré Plantio | G37: Roundup WG 720 | H37: Glifosato 720 g/kg | I37: kg/ha
C38: Controle de Insetos | E38: 3 | F38: Dessecação Pré Plantio | G38: Connor 200 SL | H38: Glufosinato 200 g/l | I38: l/ha
C39: Manejo de Doenças | E39: 3 | F39: Dessecação Pré Plantio | G39: Finale 200 SL | H39: Glufosinato 200 g/l | I39: l/ha
C40: Nutrição Foliar | E40: 3 | F40: Dessecação Pré Plantio | G40: Glufosinato Genérico 200 SL | H40: Glufosinato 200 g/l | I40: l/ha
...
